<?xml version="1.0"?>
  <robot name="simple_model">

    <link name="base_link">
      <visual>
        <geometry>
          <cylinder length="0.01" radius="0.2"/>
          <!--mesh filename="package://model_tutorial/meshes/cube.dae" /-->
        </geometry>
        <origin rpy="0 0 0" xyz="0 0 0"/>
        <material name="yellow">
          <color rgba="1 1 0 1"/>
        </material>
      </visual>
      <collision>
        <geometry>
          <cylinder length="0.01" radius="0.2"/>
        </geometry>
        <origin rpy="0 0 0" xyz="0 0 0"/>
      </collision>
      <inertial>
        <mass value="1"/>
        <inertia ixx="0.5" ixy="0.0" ixz="0.0" iyy="0.5" iyz="0.0" izz="0.5"/>
      </inertial>
    </link>

    <joint name="arm_joint" type="revolute">
      <parent link="base_link"/>
      <child link="arm_link"/>
      <origin xyz="0 0 0"/>
      <axis xyz="1 0 0" />
      <limit effort="300" velocity="0.1" lower="-3.14" upper="3.14"/>
      <dynamics damping="50" friction="1"/>
    </joint>

    <link name="arm_link">
      <visual>
        <geometry>
          <cylinder length="0.4" radius="0.04"/>
        </geometry>
        <origin rpy="0 0 0" xyz="0 0 0.2"/>
        <material name="blue">
          <color rgba="0 0 1 1"/>
        </material>
      </visual>
      <collision>
        <geometry>
          <cylinder length="0.4" radius="0.04"/>
        </geometry>
        <origin rpy="0 0 0" xyz="0 0 0.2"/>
      </collision>
      <inertial>
        <mass value="1"/>
        <inertia ixx="0.5" ixy="0.0" ixz="0.0" iyy="0.5" iyz="0.0" izz="0.5"/>
      </inertial>
    </link>

  </robot>
